\doxysection{Référence de la classe numpy.\+testing.\+\_\+private.\+utils.\+Known\+Failure\+Exception}
\hypertarget{classnumpy_1_1testing_1_1__private_1_1utils_1_1KnownFailureException}{}\label{classnumpy_1_1testing_1_1__private_1_1utils_1_1KnownFailureException}\index{numpy.testing.\_private.utils.KnownFailureException@{numpy.testing.\_private.utils.KnownFailureException}}


Graphe d\textquotesingle{}héritage de numpy.\+testing.\+\_\+private.\+utils.\+Known\+Failure\+Exception\+:
% FIG 0


Graphe de collaboration de numpy.\+testing.\+\_\+private.\+utils.\+Known\+Failure\+Exception\+:
% FIG 1


\doxysubsection{Description détaillée}
\begin{DoxyVerb}Raise this exception to mark a test as a known failing test.\end{DoxyVerb}
 

La documentation de cette classe a été générée à partir du fichier suivant \+:\begin{DoxyCompactItemize}
\item 
env/lib/python3.\+12/site-\/packages/numpy/testing/\+\_\+private/\mbox{\hyperlink{numpy_2testing_2__private_2utils_8py}{utils.\+py}}\end{DoxyCompactItemize}
